<?xml version="1.0" encoding="utf-8"?>
<!-- This URDF was automatically created by SolidWorks to URDF Exporter! Originally created by Stephen Brawner (brawner@gmail.com) 
     Commit Version: 1.6.0-4-g7f85cfe  Build Version: 1.6.7995.38578
     For more information, please see http://wiki.ros.org/sw_urdf_exporter -->
<robot
  name="ASM_Ver_1.SLDASM">
  <link
    name="base">
    <inertial>
      <origin
        xyz="0.00031852933106863 -1.41722334329578E-17 0.014039384118002"
        rpy="0 0 0" />
      <mass
        value="2.86887905675632" />
      <inertia
        ixx="0.00701430456479313"
        ixy="6.49057843002293E-07"
        ixz="9.62498131468153E-21"
        iyy="0.00708890607420914"
        iyz="-2.44389734131054E-21"
        izz="0.0138932762091189" />
    </inertial>
    <visual>
      <origin
        xyz="0 0 0"
        rpy="0 0 0" />
      <geometry>
        <mesh
          filename="package://ASM_Ver_1.SLDASM/meshes/base.STL" />
      </geometry>
      <material
        name="">
        <color
          rgba="0.792156862745098 0.819607843137255 0.933333333333333 1" />
      </material>
    </visual>
    <collision>
      <origin
        xyz="0 0 0"
        rpy="0 0 0" />
      <geometry>
        <mesh
          filename="package://ASM_Ver_1.SLDASM/meshes/base.STL" />
      </geometry>
    </collision>
  </link>
  <link
    name="left_wheel">
    <inertial>
      <origin
        xyz="0.0025901 -0.211 0"
        rpy="0 0 0" />
      <mass
        value="0.2139" />
      <inertia
        ixx="7.9925E-05"
        ixy="3.1451E-24"
        ixz="-1.6769E-22"
        iyy="0.00015706"
        iyz="-1.3278E-22"
        izz="7.9925E-05" />
    </inertial>
    <visual>
      <origin
        xyz="0 0 0"
        rpy="0 0 0" />
      <geometry>
        <mesh
          filename="package://ASM_Ver_1.SLDASM/meshes/left_wheel.STL" />
      </geometry>
      <material
        name="">
        <color
          rgba="0.79216 0.81961 0.93333 1" />
      </material>
    </visual>
    <collision>
      <origin
        xyz="0 0 0"
        rpy="0 0 0" />
      <geometry>
        <mesh
          filename="package://ASM_Ver_1.SLDASM/meshes/left_wheel.STL" />
      </geometry>
    </collision>
  </link>
  <joint
    name="left_wheel_to_base"
    type="continuous">
    <origin
      xyz="-0.00056881 0.1055 0.024488"
      rpy="0 0 0" />
    <parent
      link="base" />
    <child
      link="left_wheel" />
    <axis
      xyz="0 -1 0" />
  </joint>
  <link
    name="right_wheel">
    <inertial>
      <origin
        xyz="-0.0025901 0.211 0"
        rpy="0 0 0" />
      <mass
        value="0.2139" />
      <inertia
        ixx="7.9925E-05"
        ixy="9.3957E-24"
        ixz="-8.4185E-23"
        iyy="0.00015706"
        iyz="-5.3767E-24"
        izz="7.9925E-05" />
    </inertial>
    <visual>
      <origin
        xyz="0 0 0"
        rpy="0 0 0" />
      <geometry>
        <mesh
          filename="package://ASM_Ver_1.SLDASM/meshes/right_wheel.STL" />
      </geometry>
      <material
        name="">
        <color
          rgba="0.79216 0.81961 0.93333 1" />
      </material>
    </visual>
    <collision>
      <origin
        xyz="0 0 0"
        rpy="0 0 0" />
      <geometry>
        <mesh
          filename="package://ASM_Ver_1.SLDASM/meshes/right_wheel.STL" />
      </geometry>
    </collision>
  </link>
  <joint
    name="right_wheel_to_base"
    type="continuous">
    <origin
      xyz="0.0020213 -0.1055 0.024488"
      rpy="0 0 0" />
    <parent
      link="base" />
    <child
      link="right_wheel" />
    <axis
      xyz="0 1 0" />
  </joint>
</robot>