<?xml version="1.0" encoding="utf-8"?>
<!-- This URDF was automatically created by SolidWorks to URDF Exporter! Originally created by Stephen Brawner (brawner@gmail.com) 
     Commit Version: 1.6.0-4-g7f85cfe  Build Version: 1.6.7995.38578
     For more information, please see http://wiki.ros.org/sw_urdf_exporter -->
<robot
  name="dolly">
  <link
    name="base_link">
    <inertial>
      <origin
        xyz="0.000331307458628204 -1.13206745255336E-17 0.0146402475988973"
        rpy="0 0 0" />
      <mass
        value="2.75822986493914" />
      <inertia
        ixx="0.00701026423371661"
        ixy="4.12242135597593E-07"
        ixz="9.11222162788415E-21"
        iyy="0.00703854486847878"
        iyz="-2.96461531539005E-21"
        izz="0.0138418301358928" />
    </inertial>
    <visual>
      <origin
        xyz="0 0 0"
        rpy="0 0 0" />
      <geometry>
        <mesh
          filename="package://dolly/meshes/base_link.STL" />
      </geometry>
      <material
        name="">
        <color
          rgba="0.792156862745098 0.819607843137255 0.933333333333333 1" />
      </material>
    </visual>
    <collision>
      <origin
        xyz="0 0 0"
        rpy="0 0 0" />
      <geometry>
        <mesh
          filename="package://dolly/meshes/base_link.STL" />
      </geometry>
    </collision>
  </link>
  <link
    name="left_wheel">
    <inertial>
      <origin
        xyz="0.00259014166271363 -0.211 0"
        rpy="0 0 0" />
      <mass
        value="0.21389788050971" />
      <inertia
        ixx="7.9924596730356E-05"
        ixy="3.1451024225384E-24"
        ixz="-1.67685649879966E-22"
        iyy="0.000157056017019794"
        iyz="-1.32781947727186E-22"
        izz="7.9924596730356E-05" />
    </inertial>
    <visual>
      <origin
        xyz="0 0 0"
        rpy="0 0 0" />
      <geometry>
        <mesh
          filename="package://dolly/meshes/left_wheel.STL" />
      </geometry>
      <material
        name="">
        <color
          rgba="0.792156862745098 0.819607843137255 0.933333333333333 1" />
      </material>
    </visual>
    <collision>
      <origin
        xyz="0 0 0"
        rpy="0 0 0" />
      <geometry>
        <mesh
          filename="package://dolly/meshes/left_wheel.STL" />
      </geometry>
    </collision>
  </link>
  <joint
    name="left_wheel_to_base"
    type="continuous">
    <origin
      xyz="-0.00056881 0.1055 0.024488"
      rpy="0 0 0" />
    <parent
      link="base_link" />
    <child
      link="left_wheel" />
    <axis
      xyz="0 -1 0" />
  </joint>
  <link
    name="right_wheel">
    <inertial>
      <origin
        xyz="-0.00259014166271363 0.211 0"
        rpy="0 0 0" />
      <mass
        value="0.21389788050971" />
      <inertia
        ixx="7.9924596730356E-05"
        ixy="9.39573778283674E-24"
        ixz="-8.41846427878367E-23"
        iyy="0.000157056017019794"
        iyz="-5.37667398159315E-24"
        izz="7.9924596730356E-05" />
    </inertial>
    <visual>
      <origin
        xyz="0 0 0"
        rpy="0 0 0" />
      <geometry>
        <mesh
          filename="package://dolly/meshes/right_wheel.STL" />
      </geometry>
      <material
        name="">
        <color
          rgba="0.792156862745098 0.819607843137255 0.933333333333333 1" />
      </material>
    </visual>
    <collision>
      <origin
        xyz="0 0 0"
        rpy="0 0 0" />
      <geometry>
        <mesh
          filename="package://dolly/meshes/right_wheel.STL" />
      </geometry>
    </collision>
  </link>
  <joint
    name="right_wheel_to_base"
    type="continuous">
    <origin
      xyz="0.0020213 -0.1055 0.024488"
      rpy="0 0 0" />
    <parent
      link="base_link" />
    <child
      link="right_wheel" />
    <axis
      xyz="0 1 0" />
  </joint>
</robot>