<robot name="dolly_description">
  <link name="base_footprint">
    <visual>
      <origin xyz="0 0 0" rpy="0 0 0" />
      <geometry>
        <mesh filename="package://dolly_description/meshes/base_footprint.STL" />
      </geometry>
      <material name="">
        <color rgba="0 0 1 1" />
      </material>
    </visual>
    <collision>
      <origin xyz="0 0 0" rpy="0 0 0" />
      <geometry>
        <mesh filename="package://dolly_description/meshes/base_footprint.STL" />
      </geometry>
    </collision>
  </link>
  <link name="base_link">
    <inertial>
      <origin xyz="-0.00036303 -0.0064784 0.029771" rpy="0 0 0" />
      <mass value="3.2695" />
      <inertia ixx="0.0070458" ixy="3.5192E-06" ixz="-8.7066E-07" iyy="0.0077407" iyz="-1.1699E-06" izz="0.01347" />
    </inertial>
    <visual>
      <origin xyz="0 0 0" rpy="0 0 0" />
      <geometry>
        <mesh filename="package://dolly_description/meshes/base_link.STL" />
      </geometry>
      <material name="">
        <color rgba="0.79216 0.81961 0.93333 1" />
      </material>
    </visual>
    <collision>
      <origin xyz="0 0 0" rpy="0 0 0" />
      <geometry>
        <mesh filename="package://dolly_description/meshes/base_link.STL" />
      </geometry>
    </collision>
  </link>
  <joint name="base_link_to_footprint" type="fixed">
    <origin xyz="0 0 0.00751182436050394" rpy="0 0 0" />
    <parent link="base_footprint" />
    <child link="base_link" />
    <axis xyz="0 0 0" />
  </joint>
  <link name="left_wheel">
    <inertial>
      <origin xyz="4.3368E-19 -2.403E-05 3.4694E-18" rpy="0 0 0" />
      <mass value="0.18489" />
      <inertia ixx="7.4493E-05" ixy="7.0054E-22" ixz="-4.5267E-21" iyy="0.00014628" iyz="-8.4037E-22" izz="7.4493E-05" />
    </inertial>
    <visual>
      <origin xyz="0 0 0" rpy="0 0 0" />
      <geometry>
        <mesh filename="package://dolly_description/meshes/left_wheel.STL" />
      </geometry>
      <material name="">
        <color rgba="0 1 0 1" />
      </material>
    </visual>
    <collision>
      <origin xyz="0 0 0" rpy="0 0 0" />
      <geometry>
        <mesh filename="package://dolly_description/meshes/left_wheel.STL" />
      </geometry>
    </collision>
  </link>
  <joint name="left_wheel_to_base" type="continuous">
    <origin xyz="-0.000568807268987122 0.1068 0.0274882756394961" rpy="0 0 0" />
    <parent link="base_link" />
    <child link="left_wheel" />
    <axis xyz="0 -1 0" />
  </joint>
  <link name="right_wheel">
    <inertial>
      <origin xyz="-4.3368E-19 -2.403E-05 -3.4694E-18" rpy="0 0 0" />
      <mass value="0.18489" />
      <inertia ixx="7.4493E-05" ixy="-1.3204E-21" ixz="-3.9575E-21" iyy="0.00014628" iyz="8.3738E-22" izz="7.4493E-05" />
    </inertial>
    <visual>
      <origin xyz="0 0 0" rpy="0 0 0" />
      <geometry>
        <mesh filename="package://dolly_description/meshes/right_wheel.STL" />
      </geometry>
      <material name="">
        <color rgba="0 1 0 1" />
      </material>
    </visual>
    <collision>
      <origin xyz="0 0 0" rpy="0 0 0" />
      <geometry>
        <mesh filename="package://dolly_description/meshes/right_wheel.STL" />
      </geometry>
    </collision>
  </link>
  <joint name="right_wheel_to_base" type="continuous">
    <origin xyz="0.00202133439372744 -0.1068 0.0274882756394961" rpy="3.14159265358979 0 0" />
    <parent link="base_link" />
    <child link="right_wheel" />
    <axis xyz="0 -1 0" />
  </joint>
  <link name="front_caster">
    <inertial>
      <origin xyz="0.204 -1.7008E-18 0" rpy="0 0 0" />
      <mass value="0.00090478" />
      <inertia ixx="1.3029E-08" ixy="-1.4061E-25" ixz="6.3367E-25" iyy="1.3029E-08" iyz="-6.302E-26" izz="1.3029E-08" />
    </inertial>
    <visual>
      <origin xyz="0 0 0" rpy="0 0 0" />
      <geometry>
        <mesh filename="package://dolly_description/meshes/front_caster.STL" />
      </geometry>
      <material name="">
        <color rgba="0.79216 0.81961 0.93333 1" />
      </material>
    </visual>
    <collision>
      <origin xyz="0 0 0" rpy="0 0 0" />
      <geometry>
        <mesh filename="package://dolly_description/meshes/front_caster.STL" />
      </geometry>
    </collision>
  </link>
  <joint name="front_caster_to_base" type="fixed">
    <origin xyz="-0.102 0 -0.004" rpy="0 0 0" />
    <parent link="base_link" />
    <child link="front_caster" />
    <axis xyz="0 0 0" />
  </joint>
  <link name="back_caster">
    <inertial>
      <origin xyz="1.3878E-17 3.3881E-20 8.6736E-19" rpy="0 0 0" />
      <mass value="0.00090478" />
      <inertia ixx="1.3029E-08" ixy="-1.4061E-25" ixz="1.1034E-24" iyy="1.3029E-08" iyz="-1.8513E-25" izz="1.3029E-08" />
    </inertial>
    <visual>
      <origin xyz="0 0 0" rpy="0 0 0" />
      <geometry>
        <mesh filename="package://dolly_description/meshes/back_caster.STL" />
      </geometry>
      <material name="">
        <color rgba="0.79216 0.81961 0.93333 1" />
      </material>
    </visual>
    <collision>
      <origin xyz="0 0 0" rpy="0 0 0" />
      <geometry>
        <mesh filename="package://dolly_description/meshes/back_caster.STL" />
      </geometry>
    </collision>
  </link>
  <joint name="back_caster_to_base" type="fixed">
    <origin xyz="-0.102 0 -0.004" rpy="0 0 0" />
    <parent link="base_link" />
    <child link="back_caster" />
    <axis xyz="0 0 0" />
  </joint>

  <link name="sensors">
    <visual>
      <origin xyz="0 0 0" rpy="0 0 0" />
      <geometry>
          <box size = "0.03 0.03 0.03" />
      </geometry>
    </visual>
  </link>

  <joint name="sensors_to_base" type="fixed">
    <origin xyz="0 0 0" rpy="0 0 0" />
    <parent link="base_link" />
    <child link="sensors" />
    <axis xyz="0 0 0" />
  </joint>

</robot>